#VRML_SIM R2025a utf8
# license: Apache License 2.0
# license url: http://www.apache.org/licenses/LICENSE-2.0
# This is a proto file for Webots for the Wolfgang_orig
# Extracted from: /Users/jacobmazelin/Main-Desktop/All_Code/UM/Wolverbot_Kickers/bitbots_main_fork/webots_robot.urdf

PROTO Wolfgang_orig [
  field  SFVec3f     translation     0 0 0
  field  SFRotation  rotation        0 0 1 0
  field  SFString    name            "Wolfgang_orig"  # Is `Robot.name`.
  field  SFString    controller      "void"           # Is `Robot.controller`.
  field  MFString    controllerArgs  []               # Is `Robot.controllerArgs`.
  field  SFString    customData      ""               # Is `Robot.customData`.
  field  SFBool      supervisor      FALSE            # Is `Robot.supervisor`.
  field  SFBool      synchronization TRUE             # Is `Robot.synchronization`.
  field  SFBool      selfCollision   FALSE            # Is `Robot.selfCollision`.
]
{
  Robot {
    translation IS translation
    rotation IS rotation
    controller IS controller
    controllerArgs IS controllerArgs
    customData IS customData
    supervisor IS supervisor
    synchronization IS synchronization
    selfCollision IS selfCollision
    children [
      Pose {
        translation -0.064050 0.127106 0.080745
        rotation 0.000000 -0.000000 1.000000 1.570800
        children [
          Shape {
            appearance DEF ax_12a_material PBRAppearance {
              baseColor 0.647059 0.647059 0.647059
              roughness 1.000000
              metalness 0
            }
            geometry DEF ax_12a Mesh {
              url "e:/assets/ax_12a.stl"
            }
          }
        ]
      }
      Pose {
        translation -0.019332 0.059928 -0.006438
        rotation -0.577350 -0.577352 0.577350 2.094399
        children [
          Shape {
            appearance DEF torso_material PBRAppearance {
              baseColor 0.972549 0.529412 0.003922
              roughness 1.000000
              metalness 0
            }
            geometry DEF torso Mesh {
              url "e:/assets/torso.stl"
            }
          }
        ]
      }
      Pose {
        translation 0.004289 -0.008876 -0.001770
        rotation 0.000000 -0.000000 1.000000 1.570800
        children [
          Shape {
            appearance DEF hip_base_material PBRAppearance {
              baseColor 0.647059 0.647059 0.647059
              roughness 1.000000
              metalness 0
            }
            geometry DEF hip_base Mesh {
              url "e:/assets/hip_base.stl"
            }
          }
        ]
      }
      Pose {
        translation -0.064050 -0.123944 0.080745
        rotation 0.000000 0.000000 -1.000000 1.570800
        children [
          Shape {
            appearance DEF ax_12a_2_material PBRAppearance {
              baseColor 0.647059 0.647059 0.647059
              roughness 1.000000
              metalness 0
            }
            geometry USE ax_12a
          }
        ]
      }
      HingeJoint {
        jointParameters HingeJointParameters {
          axis -0.000004 1.000000 0.000000
          anchor -0.043923 -0.166944 0.100245
        }
        device [
          RotationalMotor {
            name "torso-left_arm"
            maxVelocity 10.0
            minPosition -2.26893
            maxPosition 2.26893
            maxTorque 10.0
          }
          PositionSensor {
            name "torso-left_arm_sensor"
          }
        ]
        endPoint Solid {
          translation -0.043923 -0.166944 0.100245
          rotation -0.577350 0.577350 0.577352 2.094399
          children [
            Pose {
              translation -0.170106 0.100245 -0.085723
              rotation 1.000000 0.000000 -0.000000 1.570800
              children [
                Shape {
                  appearance DEF left_arm_material PBRAppearance {
                    baseColor 0.231373 0.380392 0.705882
                    roughness 1.000000
                    metalness 0
                  }
                  geometry DEF left_arm Mesh {
                    url "e:/assets/left_arm.stl"
                  }
                }
              ]
            }
            HingeJoint {
              jointParameters HingeJointParameters {
                axis 0.000000 0.000000 1.000000
                anchor -0.000234 0.182000 0.001200
              }
              device [
                RotationalMotor {
                  name "arm_L_3"
                  maxVelocity 10.0
                  minPosition -1.5708
                  maxPosition 1.5708
                  maxTorque 10.0
                }
                PositionSensor {
                  name "arm_L_3_sensor"
                }
              ]
              endPoint Solid {
                translation -0.000234 0.182000 0.001200
                children [
                  Pose {
                    translation -0.176776 -0.063226 -0.094401
                    rotation 1.000000 0.000000 -0.000000 1.570800
                    children [
                      Shape {
                        appearance DEF left_hand_material PBRAppearance {
                          baseColor 0.768627 0.886275 0.952941
                          roughness 1.000000
                          metalness 0
                        }
                        geometry DEF left_hand Mesh {
                          url "e:/assets/left_hand.stl"
                        }
                      }
                    ]
                  }
                ]
                name "left_hand"
                boundingObject Group {
                  children [
                    Cylinder {
                      radius 0.00675797
                      height 0.041
                    }
                    Cylinder {
                      radius 0.00469911
                      height 0.041
                    }
                    Cylinder {
                      radius 0.00656087
                      height 0.041
                    }
                    Box {
                       size 0.031940 0.074056 0.041000
                    }
                    Box {
                       size 0.032000 0.030266 0.041000
                    }
                  ]
                }
                physics Physics {
                  density -1
                  mass 0.146964
                  centerOfMass [ 0.005440 0.067935 -0.018809 ]
                  inertiaMatrix [
                    4.458980e-04 4.349970e-05 4.417390e-04
                    -3.961950e-05 -2.404950e-07 -1.804320e-06
                  ]
                }
              }
            }
          ]
          name "left_arm"
          boundingObject Box {
             size 0.029846 0.205415 0.048000
          }
          physics Physics {
            density -1
            mass 0.121563
            centerOfMass [ -0.000084 0.065162 -0.017296 ]
            inertiaMatrix [
              4.980830e-04 4.380200e-05 4.744900e-04
              4.927270e-07 1.934220e-08 -1.760070e-05
            ]
          }
        }
      }
      HingeJoint {
        jointParameters HingeJointParameters {
          axis 0.000004 -1.000000 0.000003
          anchor -0.043923 0.170106 0.100245
        }
        device [
          RotationalMotor {
            name "torso-right_arm"
            maxVelocity 10.0
            minPosition -2.35619
            maxPosition 2.35619
            maxTorque 10.0
          }
          PositionSensor {
            name "torso-right_arm_sensor"
          }
        ]
        endPoint Solid {
          translation -0.043923 0.170106 0.100245
          rotation 0.577350 0.577350 -0.577350 2.094389
          children [
            Pose {
              translation 0.166944 0.100245 -0.085723
              rotation 1.000000 0.000000 -0.000000 1.570800
              children [
                Shape {
                  appearance DEF right_arm_material PBRAppearance {
                    baseColor 0.231373 0.380392 0.705882
                    roughness 1.000000
                    metalness 0
                  }
                  geometry DEF right_arm Mesh {
                    url "e:/assets/right_arm.stl"
                  }
                }
              ]
            }
            HingeJoint {
              jointParameters HingeJointParameters {
                axis 0.000000 0.000000 1.000000
                anchor -0.000457 0.181999 0.001200
              }
              device [
                RotationalMotor {
                  name "arm_R_3"
                  maxVelocity 10.0
                  minPosition -1.5708
                  maxPosition 1.5708
                  maxTorque 10.0
                }
                PositionSensor {
                  name "arm_R_3_sensor"
                }
              ]
              endPoint Solid {
                translation -0.000457 0.181999 0.001200
                children [
                  Pose {
                    translation 0.167604 -0.081128 -0.086117
                    rotation 1.000000 0.000000 -0.000000 1.570800
                    children [
                      Shape {
                        appearance DEF right_hand_material PBRAppearance {
                          baseColor 0.498039 0.498039 0.498039
                          roughness 1.000000
                          metalness 0
                        }
                        geometry DEF right_hand Mesh {
                          url "e:/assets/right_hand.stl"
                        }
                      }
                    ]
                  }
                ]
                name "right_hand"
                boundingObject Group {
                  children [
                    Cylinder {
                      radius 0.00661638
                      height 0.041
                    }
                    Cylinder {
                      radius 0.005
                      height 0.041
                    }
                    Box {
                       size 0.028653 0.102703 0.041000
                    }
                    Cylinder {
                      radius 0.00725035
                      height 0.041
                    }
                  ]
                }
                physics Physics {
                  density -1
                  mass 0.144242
                  centerOfMass [ -0.005698 0.067914 -0.019200 ]
                  inertiaMatrix [
                    4.373220e-04 4.297760e-05 4.335580e-04
                    4.038410e-05 8.685300e-09 -1.103250e-07
                  ]
                }
              }
            }
          ]
          name "right_arm"
          boundingObject Box {
             size 0.031127 0.205631 0.048000
          }
          physics Physics {
            density -1
            mass 0.121563
            centerOfMass [ -0.000163 0.065162 -0.017296 ]
            inertiaMatrix [
              4.980820e-04 4.380380e-05 4.744900e-04
              1.047460e-06 4.083500e-08 -1.760070e-05
            ]
          }
        }
      }
      HingeJoint {
        jointParameters HingeJointParameters {
          axis 0.000000 -0.000000 1.000000
          anchor -0.064050 -0.062987 -0.166455
        }
        device [
          RotationalMotor {
            name "hip_right_z"
            maxVelocity 10.0
            minPosition -0.785398
            maxPosition 0.785398
            maxTorque 10.0
          }
          PositionSensor {
            name "hip_right_z_sensor"
          }
        ]
        endPoint Solid {
          translation -0.064050 -0.062987 -0.166455
          rotation 0.000000 -0.000000 1.000000 1.570800
          children [
            Pose {
              translation -0.000000 0.054500 -0.042000
              rotation -0.000001 1.000000 -0.000001 3.141593
              children [
                Shape {
                  appearance DEF rx_64_material PBRAppearance {
                    baseColor 0.647059 0.647059 0.647059
                    roughness 1.000000
                    metalness 0
                  }
                  geometry DEF rx_64 Mesh {
                    url "e:/assets/rx_64.stl"
                  }
                }
              ]
            }
            Pose {
              translation 0.062973 -0.066050 0.165680
              children [
                Shape {
                  appearance DEF hip_right_z_material PBRAppearance {
                    baseColor 0.615686 0.811765 0.929412
                    roughness 1.000000
                    metalness 0
                  }
                  geometry DEF hip_right_z Mesh {
                    url "e:/assets/hip_right_z.stl"
                  }
                }
              ]
            }
            HingeJoint {
              jointParameters HingeJointParameters {
                axis 0.000006 1.000000 -0.000000
                anchor 0.005100 0.002483 -0.077000
              }
              device [
                RotationalMotor {
                  name "hip_right_z-right_thigh"
                  maxVelocity 10.0
                  minPosition -0.785398
                  maxPosition 0.523599
                  maxTorque 10.0
                }
                PositionSensor {
                  name "hip_right_z-right_thigh_sensor"
                }
              ]
              endPoint Solid {
                translation 0.005100 0.002483 -0.077000
                rotation -0.577348 0.577353 0.577350 2.094394
                children [
                  Pose {
                    translation -0.087490 -0.266468 -0.044423
                    rotation 0.577350 0.577350 -0.577352 2.094399
                    children [
                      Shape {
                        appearance DEF right_thigh_material PBRAppearance {
                          baseColor 0.647059 0.647059 0.647059
                          roughness 1.000000
                          metalness 0
                        }
                        geometry DEF right_thigh Mesh {
                          url "e:/assets/right_thigh.stl"
                        }
                      }
                    ]
                  }
                  HingeJoint {
                    jointParameters HingeJointParameters {
                      axis -1.000000 -0.000003 0.000003
                      anchor 0.127273 0.290550 0.005200
                    }
                    device [
                      RotationalMotor {
                        name "right_thigh-right_foot"
                        maxVelocity 10.0
                        minPosition -1.0472
                        maxPosition 1.5708
                        maxTorque 10.0
                      }
                      PositionSensor {
                        name "right_thigh-right_foot_sensor"
                      }
                    ]
                    endPoint Solid {
                      translation 0.127273 0.290550 0.005200
                      rotation 0.540717 -0.644400 -0.540717 1.996731
                      children [
                        Pose {
                          translation 0.000655 0.022000 0.001705
                          rotation 0.000987 0.707108 0.707105 3.143563
                          children [
                            Shape {
                              appearance DEF right_foot_material PBRAppearance {
                                baseColor 0.972549 0.529412 0.003922
                                roughness 1.000000
                                metalness 0
                              }
                              geometry DEF right_foot Mesh {
                                url "e:/assets/right_foot.stl"
                              }
                            }
                          ]
                        }
                      ]
                      name "right_foot"
                      boundingObject Group {
                        children [
                          Box {
                             size 0.040000 0.010139 0.010000
                          }
                          Box {
                             size 0.060279 0.099832 0.010000
                          }
                        ]
                      }
                      physics Physics {
                        density -1
                        mass 0.132264
                        centerOfMass [ 0.000534 0.014550 0.000278 ]
                        inertiaMatrix [
                          1.133170e-04 1.470880e-04 4.353010e-05
                          -2.313460e-07 -7.027320e-09 -2.051250e-06
                        ]
                      }
                    }
                  }
                ]
                name "right_thigh"
                boundingObject Group {
                  children [
                    Box {
                       size 0.039273 0.134878 0.058000
                    }
                    Box {
                       size 0.017430 0.017905 0.058000
                    }
                    Box {
                       size 0.022424 0.022441 0.058000
                    }
                  ]
                }
                physics Physics {
                  density -1
                  mass 0.596928
                  centerOfMass [ -0.000360 0.074325 0.027274 ]
                  inertiaMatrix [
                    1.677770e-03 6.448560e-04 1.183070e-03
                    4.306350e-06 1.063100e-06 1.815300e-05
                  ]
                }
              }
            }
          ]
          name "hip_right_z"
          boundingObject Group {
            children [
              Box {
                 size 0.039681 0.045940 0.034000
              }
              Box {
                 size 0.031190 0.005861 0.034000
              }
              Box {
                 size 0.031786 0.007110 0.034000
              }
            ]
          }
          physics Physics {
            density -1
            mass 0.051771
            centerOfMass [ -0.000000 0.003339 -0.023945 ]
            inertiaMatrix [
              4.053250e-05 1.697260e-05 3.528020e-05
              2.724580e-14 -6.103760e-15 1.806780e-06
            ]
          }
        }
      }
      HingeJoint {
        jointParameters HingeJointParameters {
          axis 0.000000 -0.000000 1.000000
          anchor -0.064050 0.066181 -0.166455
        }
        device [
          RotationalMotor {
            name "hip_left_z"
            maxVelocity 10.0
            minPosition -0.785398
            maxPosition 0.785398
            maxTorque 10.0
          }
          PositionSensor {
            name "hip_left_z_sensor"
          }
        ]
        endPoint Solid {
          translation -0.064050 0.066181 -0.166455
          rotation 0.000000 -0.000000 1.000000 1.570800
          children [
            Pose {
              translation -0.025868 -0.073826 0.175355
              children [
                Shape {
                  appearance DEF hip_left_z_material PBRAppearance {
                    baseColor 0.615686 0.811765 0.929412
                    roughness 1.000000
                    metalness 0
                  }
                  geometry DEF hip_left_z Mesh {
                    url "e:/assets/hip_left_z.stl"
                  }
                }
              ]
            }
            Pose {
              translation -0.000000 0.054500 -0.042000
              rotation 0.000001 -1.000000 -0.000001 3.141593
              children [
                Shape {
                  appearance DEF rx_64_2_material PBRAppearance {
                    baseColor 0.647059 0.647059 0.647059
                    roughness 1.000000
                    metalness 0
                  }
                  geometry USE rx_64
                }
              ]
            }
            HingeJoint {
              jointParameters HingeJointParameters {
                axis -0.000004 -1.000000 0.000000
                anchor -0.005100 0.002483 -0.077000
              }
              device [
                RotationalMotor {
                  name "hip_left_z-left_thigh"
                  maxVelocity 10.0
                  minPosition -0.523599
                  maxPosition 0.785398
                  maxTorque 10.0
                }
                PositionSensor {
                  name "hip_left_z-left_thigh_sensor"
                }
              ]
              endPoint Solid {
                translation -0.005100 0.002483 -0.077000
                rotation 0.577350 0.577350 -0.577352 2.094399
                children [
                  Pose {
                    translation -0.062389 0.234965 -0.077854
                    rotation -0.577350 -0.577350 -0.577352 2.094399
                    children [
                      Shape {
                        appearance DEF left_thigh_material PBRAppearance {
                          baseColor 0.647059 0.647059 0.647059
                          roughness 1.000000
                          metalness 0
                        }
                        geometry DEF left_thigh Mesh {
                          url "e:/assets/left_thigh.stl"
                        }
                      }
                    ]
                  }
                  HingeJoint {
                    jointParameters HingeJointParameters {
                      axis 1.000000 -0.000003 -0.000000
                      anchor 0.117972 -0.298880 0.005000
                    }
                    device [
                      RotationalMotor {
                        name "left_thigh-left_foot"
                        maxVelocity 10.0
                        minPosition -1.0472
                        maxPosition 1.5708
                        maxTorque 10.0
                      }
                      PositionSensor {
                        name "left_thigh-left_foot_sensor"
                      }
                    ]
                    endPoint Solid {
                      translation 0.117972 -0.298880 0.005000
                      rotation -0.540714 0.644402 -0.540716 1.996735
                      children [
                        Pose {
                          translation -0.077108 0.498310 -0.054992
                          rotation 0.998325 0.052772 0.023709 2.587507
                          children [
                            Shape {
                              appearance DEF left_foot_material PBRAppearance {
                                baseColor 0.972549 0.529412 0.003922
                                roughness 1.000000
                                metalness 0
                              }
                              geometry DEF left_foot Mesh {
                                url "e:/assets/left_foot.stl"
                              }
                            }
                          ]
                        }
                      ]
                      name "left_foot"
                      boundingObject Group {
                        children [
                          Box {
                             size 0.061605 0.099019 0.010000
                          }
                          Box {
                             size 0.039995 0.010805 0.010000
                          }
                        ]
                      }
                      physics Physics {
                        density -1
                        mass 0.132264
                        centerOfMass [ 0.000044 -0.014550 0.000278 ]
                        inertiaMatrix [
                          1.133170e-04 1.470800e-04 4.352240e-05
                          2.140060e-07 -4.111070e-09 2.051260e-06
                        ]
                      }
                    }
                  }
                ]
                name "left_thigh"
                boundingObject Group {
                  children [
                    Box {
                       size 0.040000 0.129557 0.058000
                    }
                    Box {
                       size 0.022425 0.023953 0.058000
                    }
                    Box {
                       size 0.017430 0.018060 0.058000
                    }
                  ]
                }
                physics Physics {
                  density -1
                  mass 0.606907
                  centerOfMass [ -0.000041 -0.074317 0.027274 ]
                  inertiaMatrix [
                    1.706200e-03 6.556190e-04 1.203220e-03
                    -1.287560e-06 -1.180370e-06 -1.857460e-05
                  ]
                }
              }
            }
          ]
          name "hip_left_z"
          boundingObject Group {
            children [
              Box {
                 size 0.039681 0.045940 0.034000
              }
              Box {
                 size 0.031190 0.005861 0.034000
              }
              Box {
                 size 0.031786 0.007110 0.034000
              }
            ]
          }
          physics Physics {
            density -1
            mass 0.051771
            centerOfMass [ -0.000000 0.003339 -0.023945 ]
            inertiaMatrix [
              4.053250e-05 1.697260e-05 3.528020e-05
              2.724580e-14 -6.103770e-15 1.806780e-06
            ]
          }
        }
      }
    ]
    name IS name
    boundingObject Group {
      children [
        Box {
           size 0.036550 0.049266 0.026000
        }
        Box {
           size 0.200000 0.052720 0.055000
        }
        Box {
           size 0.036550 0.049266 0.026000
        }
      ]
    }
    physics Physics {
      density -1
      mass 5.395480
      centerOfMass [ -0.056154 0.001047 -0.002386 ]
      inertiaMatrix [
        7.833730e-02 5.407050e-02 3.299430e-02
        3.494340e-05 -2.730160e-04 -1.211320e-05
      ]
    }
  }
}
